{
 "cells": [
  {
   "cell_type": "code",
   "execution_count": null,
   "metadata": {},
   "outputs": [],
   "source": [
    "import sqlalchemy\n",
    "#from sqlalchemy import URL\n",
    "from sqlalchemy.engine import create_engine"
   ]
  },
  {
   "cell_type": "code",
   "execution_count": 2,
   "metadata": {},
   "outputs": [
    {
     "ename": "ModuleNotFoundError",
     "evalue": "No module named 'psycopg2'",
     "output_type": "error",
     "traceback": [
      "\u001b[1;31m---------------------------------------------------------------------------\u001b[0m",
      "\u001b[1;31mModuleNotFoundError\u001b[0m                       Traceback (most recent call last)",
      "Cell \u001b[1;32mIn[2], line 11\u001b[0m\n\u001b[0;32m      1\u001b[0m \u001b[38;5;66;03m#url_object = URL.create(\u001b[39;00m\n\u001b[0;32m      2\u001b[0m     \u001b[38;5;66;03m#\"postgresql\",\u001b[39;00m\n\u001b[0;32m      3\u001b[0m     \u001b[38;5;66;03m#username=\"postgresql\",\u001b[39;00m\n\u001b[1;32m   (...)\u001b[0m\n\u001b[0;32m      8\u001b[0m \n\u001b[0;32m      9\u001b[0m \u001b[38;5;66;03m#engine = create_engine(url_object)\u001b[39;00m\n\u001b[1;32m---> 11\u001b[0m engine \u001b[38;5;241m=\u001b[39m sqlalchemy\u001b[38;5;241m.\u001b[39mcreate_engine(\u001b[38;5;124m'\u001b[39m\u001b[38;5;124mpostgresql://postgres:postgres@localhost:5432/dogs\u001b[39m\u001b[38;5;124m'\u001b[39m)\n",
      "File \u001b[1;32m<string>:2\u001b[0m, in \u001b[0;36mcreate_engine\u001b[1;34m(url, **kwargs)\u001b[0m\n",
      "File \u001b[1;32m~\\anaconda3\\Lib\\site-packages\\sqlalchemy\\util\\deprecations.py:309\u001b[0m, in \u001b[0;36mdeprecated_params.<locals>.decorate.<locals>.warned\u001b[1;34m(fn, *args, **kwargs)\u001b[0m\n\u001b[0;32m    302\u001b[0m     \u001b[38;5;28;01mif\u001b[39;00m m \u001b[38;5;129;01min\u001b[39;00m kwargs:\n\u001b[0;32m    303\u001b[0m         _warn_with_version(\n\u001b[0;32m    304\u001b[0m             messages[m],\n\u001b[0;32m    305\u001b[0m             versions[m],\n\u001b[0;32m    306\u001b[0m             version_warnings[m],\n\u001b[0;32m    307\u001b[0m             stacklevel\u001b[38;5;241m=\u001b[39m\u001b[38;5;241m3\u001b[39m,\n\u001b[0;32m    308\u001b[0m         )\n\u001b[1;32m--> 309\u001b[0m \u001b[38;5;28;01mreturn\u001b[39;00m fn(\u001b[38;5;241m*\u001b[39margs, \u001b[38;5;241m*\u001b[39m\u001b[38;5;241m*\u001b[39mkwargs)\n",
      "File \u001b[1;32m~\\anaconda3\\Lib\\site-packages\\sqlalchemy\\engine\\create.py:560\u001b[0m, in \u001b[0;36mcreate_engine\u001b[1;34m(url, **kwargs)\u001b[0m\n\u001b[0;32m    558\u001b[0m         \u001b[38;5;28;01mif\u001b[39;00m k \u001b[38;5;129;01min\u001b[39;00m kwargs:\n\u001b[0;32m    559\u001b[0m             dbapi_args[k] \u001b[38;5;241m=\u001b[39m pop_kwarg(k)\n\u001b[1;32m--> 560\u001b[0m     dbapi \u001b[38;5;241m=\u001b[39m dialect_cls\u001b[38;5;241m.\u001b[39mdbapi(\u001b[38;5;241m*\u001b[39m\u001b[38;5;241m*\u001b[39mdbapi_args)\n\u001b[0;32m    562\u001b[0m dialect_args[\u001b[38;5;124m\"\u001b[39m\u001b[38;5;124mdbapi\u001b[39m\u001b[38;5;124m\"\u001b[39m] \u001b[38;5;241m=\u001b[39m dbapi\n\u001b[0;32m    564\u001b[0m dialect_args\u001b[38;5;241m.\u001b[39msetdefault(\u001b[38;5;124m\"\u001b[39m\u001b[38;5;124mcompiler_linting\u001b[39m\u001b[38;5;124m\"\u001b[39m, compiler\u001b[38;5;241m.\u001b[39mNO_LINTING)\n",
      "File \u001b[1;32m~\\anaconda3\\Lib\\site-packages\\sqlalchemy\\dialects\\postgresql\\psycopg2.py:782\u001b[0m, in \u001b[0;36mPGDialect_psycopg2.dbapi\u001b[1;34m(cls)\u001b[0m\n\u001b[0;32m    780\u001b[0m \u001b[38;5;129m@classmethod\u001b[39m\n\u001b[0;32m    781\u001b[0m \u001b[38;5;28;01mdef\u001b[39;00m \u001b[38;5;21mdbapi\u001b[39m(\u001b[38;5;28mcls\u001b[39m):\n\u001b[1;32m--> 782\u001b[0m     \u001b[38;5;28;01mimport\u001b[39;00m \u001b[38;5;21;01mpsycopg2\u001b[39;00m\n\u001b[0;32m    784\u001b[0m     \u001b[38;5;28;01mreturn\u001b[39;00m psycopg2\n",
      "\u001b[1;31mModuleNotFoundError\u001b[0m: No module named 'psycopg2'"
     ]
    }
   ],
   "source": [
    "#url_object = URL.create(\n",
    "    #\"postgresql\",\n",
    "    #username=\"postgresql\",\n",
    "    #password=\"postgres\",  # plain (unescaped) text\n",
    "    #host=\"5050\",\n",
    "    #database=\"dog\",\n",
    "#)\n",
    "\n",
    "#engine = create_engine(url_object)\n",
    "\n",
    "engine = sqlalchemy.create_engine('postgresql://postgres:postgres@localhost:5432/dogs')\n",
    "\n",
    "#engine2 = sqlalchemy.create_engine(\"postgresql://postgres:your_password@localhost:5432/dogimages\")"
   ]
  },
  {
   "cell_type": "code",
   "execution_count": 9,
   "metadata": {},
   "outputs": [
    {
     "name": "stdout",
     "output_type": "stream",
     "text": [
      "The sql extension is already loaded. To reload it, use:\n",
      "  %reload_ext sql\n"
     ]
    }
   ],
   "source": [
    "%load_ext sql\n",
    "%reload_ext sql"
   ]
  },
  {
   "cell_type": "code",
   "execution_count": 10,
   "metadata": {},
   "outputs": [
    {
     "name": "stdout",
     "output_type": "stream",
     "text": [
      "Traceback (most recent call last):\n",
      "  File \"c:\\Users\\Steve\\anaconda3\\envs\\dev\\lib\\site-packages\\sqlalchemy\\engine\\base.py\", line 145, in __init__\n",
      "    self._dbapi_connection = engine.raw_connection()\n",
      "  File \"c:\\Users\\Steve\\anaconda3\\envs\\dev\\lib\\site-packages\\sqlalchemy\\engine\\base.py\", line 3292, in raw_connection\n",
      "    return self.pool.connect()\n",
      "  File \"c:\\Users\\Steve\\anaconda3\\envs\\dev\\lib\\site-packages\\sqlalchemy\\pool\\base.py\", line 452, in connect\n",
      "    return _ConnectionFairy._checkout(self)\n",
      "  File \"c:\\Users\\Steve\\anaconda3\\envs\\dev\\lib\\site-packages\\sqlalchemy\\pool\\base.py\", line 1269, in _checkout\n",
      "    fairy = _ConnectionRecord.checkout(pool)\n",
      "  File \"c:\\Users\\Steve\\anaconda3\\envs\\dev\\lib\\site-packages\\sqlalchemy\\pool\\base.py\", line 716, in checkout\n",
      "    rec = pool._do_get()\n",
      "  File \"c:\\Users\\Steve\\anaconda3\\envs\\dev\\lib\\site-packages\\sqlalchemy\\pool\\impl.py\", line 169, in _do_get\n",
      "    with util.safe_reraise():\n",
      "  File \"c:\\Users\\Steve\\anaconda3\\envs\\dev\\lib\\site-packages\\sqlalchemy\\util\\langhelpers.py\", line 146, in __exit__\n",
      "    raise exc_value.with_traceback(exc_tb)\n",
      "  File \"c:\\Users\\Steve\\anaconda3\\envs\\dev\\lib\\site-packages\\sqlalchemy\\pool\\impl.py\", line 167, in _do_get\n",
      "    return self._create_connection()\n",
      "  File \"c:\\Users\\Steve\\anaconda3\\envs\\dev\\lib\\site-packages\\sqlalchemy\\pool\\base.py\", line 393, in _create_connection\n",
      "    return _ConnectionRecord(self)\n",
      "  File \"c:\\Users\\Steve\\anaconda3\\envs\\dev\\lib\\site-packages\\sqlalchemy\\pool\\base.py\", line 678, in __init__\n",
      "    self.__connect()\n",
      "  File \"c:\\Users\\Steve\\anaconda3\\envs\\dev\\lib\\site-packages\\sqlalchemy\\pool\\base.py\", line 902, in __connect\n",
      "    with util.safe_reraise():\n",
      "  File \"c:\\Users\\Steve\\anaconda3\\envs\\dev\\lib\\site-packages\\sqlalchemy\\util\\langhelpers.py\", line 146, in __exit__\n",
      "    raise exc_value.with_traceback(exc_tb)\n",
      "  File \"c:\\Users\\Steve\\anaconda3\\envs\\dev\\lib\\site-packages\\sqlalchemy\\pool\\base.py\", line 898, in __connect\n",
      "    self.dbapi_connection = connection = pool._invoke_creator(self)\n",
      "  File \"c:\\Users\\Steve\\anaconda3\\envs\\dev\\lib\\site-packages\\sqlalchemy\\engine\\create.py\", line 637, in connect\n",
      "    return dialect.connect(*cargs, **cparams)\n",
      "  File \"c:\\Users\\Steve\\anaconda3\\envs\\dev\\lib\\site-packages\\sqlalchemy\\engine\\default.py\", line 616, in connect\n",
      "    return self.loaded_dbapi.connect(*cargs, **cparams)\n",
      "  File \"c:\\Users\\Steve\\anaconda3\\envs\\dev\\lib\\site-packages\\psycopg2\\__init__.py\", line 122, in connect\n",
      "    conn = _connect(dsn, connection_factory=connection_factory, **kwasync)\n",
      "psycopg2.OperationalError: connection to server at \"localhost\" (::1), port 5432 failed: FATAL:  password authentication failed for user \"postgres\"\n",
      "\n",
      "\n",
      "The above exception was the direct cause of the following exception:\n",
      "\n",
      "Traceback (most recent call last):\n",
      "  File \"c:\\Users\\Steve\\anaconda3\\envs\\dev\\lib\\site-packages\\sql\\magic.py\", line 196, in execute\n",
      "    conn = sql.connection.Connection.set(\n",
      "  File \"c:\\Users\\Steve\\anaconda3\\envs\\dev\\lib\\site-packages\\sql\\connection.py\", line 70, in set\n",
      "    cls.current = existing or Connection(descriptor, connect_args, creator)\n",
      "  File \"c:\\Users\\Steve\\anaconda3\\envs\\dev\\lib\\site-packages\\sql\\connection.py\", line 55, in __init__\n",
      "    self.internal_connection = engine.connect()\n",
      "  File \"c:\\Users\\Steve\\anaconda3\\envs\\dev\\lib\\site-packages\\sqlalchemy\\engine\\base.py\", line 3268, in connect\n",
      "    return self._connection_cls(self)\n",
      "  File \"c:\\Users\\Steve\\anaconda3\\envs\\dev\\lib\\site-packages\\sqlalchemy\\engine\\base.py\", line 147, in __init__\n",
      "    Connection._handle_dbapi_exception_noconnection(\n",
      "  File \"c:\\Users\\Steve\\anaconda3\\envs\\dev\\lib\\site-packages\\sqlalchemy\\engine\\base.py\", line 2430, in _handle_dbapi_exception_noconnection\n",
      "    raise sqlalchemy_exception.with_traceback(exc_info[2]) from e\n",
      "  File \"c:\\Users\\Steve\\anaconda3\\envs\\dev\\lib\\site-packages\\sqlalchemy\\engine\\base.py\", line 145, in __init__\n",
      "    self._dbapi_connection = engine.raw_connection()\n",
      "  File \"c:\\Users\\Steve\\anaconda3\\envs\\dev\\lib\\site-packages\\sqlalchemy\\engine\\base.py\", line 3292, in raw_connection\n",
      "    return self.pool.connect()\n",
      "  File \"c:\\Users\\Steve\\anaconda3\\envs\\dev\\lib\\site-packages\\sqlalchemy\\pool\\base.py\", line 452, in connect\n",
      "    return _ConnectionFairy._checkout(self)\n",
      "  File \"c:\\Users\\Steve\\anaconda3\\envs\\dev\\lib\\site-packages\\sqlalchemy\\pool\\base.py\", line 1269, in _checkout\n",
      "    fairy = _ConnectionRecord.checkout(pool)\n",
      "  File \"c:\\Users\\Steve\\anaconda3\\envs\\dev\\lib\\site-packages\\sqlalchemy\\pool\\base.py\", line 716, in checkout\n",
      "    rec = pool._do_get()\n",
      "  File \"c:\\Users\\Steve\\anaconda3\\envs\\dev\\lib\\site-packages\\sqlalchemy\\pool\\impl.py\", line 169, in _do_get\n",
      "    with util.safe_reraise():\n",
      "  File \"c:\\Users\\Steve\\anaconda3\\envs\\dev\\lib\\site-packages\\sqlalchemy\\util\\langhelpers.py\", line 146, in __exit__\n",
      "    raise exc_value.with_traceback(exc_tb)\n",
      "  File \"c:\\Users\\Steve\\anaconda3\\envs\\dev\\lib\\site-packages\\sqlalchemy\\pool\\impl.py\", line 167, in _do_get\n",
      "    return self._create_connection()\n",
      "  File \"c:\\Users\\Steve\\anaconda3\\envs\\dev\\lib\\site-packages\\sqlalchemy\\pool\\base.py\", line 393, in _create_connection\n",
      "    return _ConnectionRecord(self)\n",
      "  File \"c:\\Users\\Steve\\anaconda3\\envs\\dev\\lib\\site-packages\\sqlalchemy\\pool\\base.py\", line 678, in __init__\n",
      "    self.__connect()\n",
      "  File \"c:\\Users\\Steve\\anaconda3\\envs\\dev\\lib\\site-packages\\sqlalchemy\\pool\\base.py\", line 902, in __connect\n",
      "    with util.safe_reraise():\n",
      "  File \"c:\\Users\\Steve\\anaconda3\\envs\\dev\\lib\\site-packages\\sqlalchemy\\util\\langhelpers.py\", line 146, in __exit__\n",
      "    raise exc_value.with_traceback(exc_tb)\n",
      "  File \"c:\\Users\\Steve\\anaconda3\\envs\\dev\\lib\\site-packages\\sqlalchemy\\pool\\base.py\", line 898, in __connect\n",
      "    self.dbapi_connection = connection = pool._invoke_creator(self)\n",
      "  File \"c:\\Users\\Steve\\anaconda3\\envs\\dev\\lib\\site-packages\\sqlalchemy\\engine\\create.py\", line 637, in connect\n",
      "    return dialect.connect(*cargs, **cparams)\n",
      "  File \"c:\\Users\\Steve\\anaconda3\\envs\\dev\\lib\\site-packages\\sqlalchemy\\engine\\default.py\", line 616, in connect\n",
      "    return self.loaded_dbapi.connect(*cargs, **cparams)\n",
      "  File \"c:\\Users\\Steve\\anaconda3\\envs\\dev\\lib\\site-packages\\psycopg2\\__init__.py\", line 122, in connect\n",
      "    conn = _connect(dsn, connection_factory=connection_factory, **kwasync)\n",
      "sqlalchemy.exc.OperationalError: (psycopg2.OperationalError) connection to server at \"localhost\" (::1), port 5432 failed: FATAL:  password authentication failed for user \"postgres\"\n",
      "\n",
      "(Background on this error at: https://sqlalche.me/e/20/e3q8)\n",
      "\n",
      "Connection info needed in SQLAlchemy format, example:\n",
      "               postgresql://username:password@hostname/dbname\n",
      "               or an existing connection: dict_keys([])\n"
     ]
    }
   ],
   "source": [
    "%sql $engine.url"
   ]
  },
  {
   "cell_type": "code",
   "execution_count": 99,
   "metadata": {},
   "outputs": [
    {
     "name": "stdout",
     "output_type": "stream",
     "text": [
      "Traceback (most recent call last):\n",
      "  File \"c:\\Users\\Steve\\anaconda3\\envs\\dev\\lib\\site-packages\\sql\\magic.py\", line 196, in execute\n",
      "    conn = sql.connection.Connection.set(\n",
      "  File \"c:\\Users\\Steve\\anaconda3\\envs\\dev\\lib\\site-packages\\sql\\connection.py\", line 82, in set\n",
      "    raise ConnectionError(\n",
      "sql.connection.ConnectionError: Environment variable $DATABASE_URL not set, and no connect string given.\n",
      "\n",
      "Connection info needed in SQLAlchemy format, example:\n",
      "               postgresql://username:password@hostname/dbname\n",
      "               or an existing connection: dict_keys([])\n"
     ]
    }
   ],
   "source": [
    "%sql \"Select * From dogpictures\""
   ]
  },
  {
   "cell_type": "code",
   "execution_count": null,
   "metadata": {},
   "outputs": [],
   "source": [
    "#how to save images to SQL table\n",
    "\n",
    "'''ArithmeticError\n",
    "\n",
    "pg_read_binary_file('/path-to-image/')\n",
    "\n",
    "'''"
   ]
  }
 ],
 "metadata": {
  "kernelspec": {
   "display_name": "Python 3 (ipykernel)",
   "language": "python",
   "name": "python3"
  },
  "language_info": {
   "name": "python",
   "version": "3.11.5"
  }
 },
 "nbformat": 4,
 "nbformat_minor": 2
}
